INFO:django.utils.autoreload:/home/rahul/conda_ws/django_ws/email_tracker/tracking/email_utils.py changed, reloading.
INFO:django.utils.autoreload:/home/rahul/conda_ws/django_ws/email_tracker/tracking/email_utils.py changed, reloading.
ERROR:django.request:Internal Server Error: /batch/
Traceback (most recent call last):
  File "/home/rahul/anaconda3/envs/tracker/lib/python3.10/site-packages/django/core/handlers/exception.py", line 56, in inner
    response = get_response(request)
  File "/home/rahul/anaconda3/envs/tracker/lib/python3.10/site-packages/django/core/handlers/base.py", line 197, in _get_response
    response = wrapped_callback(request, *callback_args, **callback_kwargs)
  File "/home/rahul/conda_ws/django_ws/email_tracker/tracking/views.py", line 107, in batch_email_view
    email_batch.emails.add(email)
  File "/home/rahul/anaconda3/envs/tracker/lib/python3.10/site-packages/django/db/models/fields/related_descriptors.py", line 1087, in add
    self._add_items(
  File "/home/rahul/anaconda3/envs/tracker/lib/python3.10/site-packages/django/db/models/fields/related_descriptors.py", line 1323, in _add_items
    target_ids = self._get_target_ids(target_field_name, objs)
  File "/home/rahul/anaconda3/envs/tracker/lib/python3.10/site-packages/django/db/models/fields/related_descriptors.py", line 1239, in _get_target_ids
    raise ValueError(
ValueError: Cannot add "<Email: Email object (None)>": instance is on database "default", value is on database "None"
ERROR:django.request:Internal Server Error: /batch/
Traceback (most recent call last):
  File "/home/rahul/anaconda3/envs/tracker/lib/python3.10/site-packages/django/core/handlers/exception.py", line 56, in inner
    response = get_response(request)
  File "/home/rahul/anaconda3/envs/tracker/lib/python3.10/site-packages/django/core/handlers/base.py", line 197, in _get_response
    response = wrapped_callback(request, *callback_args, **callback_kwargs)
  File "/home/rahul/conda_ws/django_ws/email_tracker/tracking/views.py", line 107, in batch_email_view
    email_batch.emails.add(email)
  File "/home/rahul/anaconda3/envs/tracker/lib/python3.10/site-packages/django/db/models/fields/related_descriptors.py", line 1087, in add
    self._add_items(
  File "/home/rahul/anaconda3/envs/tracker/lib/python3.10/site-packages/django/db/models/fields/related_descriptors.py", line 1323, in _add_items
    target_ids = self._get_target_ids(target_field_name, objs)
  File "/home/rahul/anaconda3/envs/tracker/lib/python3.10/site-packages/django/db/models/fields/related_descriptors.py", line 1239, in _get_target_ids
    raise ValueError(
ValueError: Cannot add "<Email: Email object (None)>": instance is on database "default", value is on database "None"
INFO:django.utils.autoreload:/home/rahul/conda_ws/django_ws/email_tracker/tracking/views.py changed, reloading.
WARNING:django.request:Not Found: /favicon.ico
INFO:django.utils.autoreload:/home/rahul/conda_ws/django_ws/email_tracker/tracking/tasks.py changed, reloading.
INFO:django.utils.autoreload:/home/rahul/conda_ws/django_ws/email_tracker/tracking/email_utils.py changed, reloading.
INFO:django.utils.autoreload:/home/rahul/conda_ws/django_ws/email_tracker/tracking/views.py changed, reloading.
INFO:django.utils.autoreload:/home/rahul/conda_ws/django_ws/email_tracker/tracking/views.py changed, reloading.
INFO:django.utils.autoreload:/home/rahul/conda_ws/django_ws/email_tracker/tracking/views.py changed, reloading.
ERROR:django.request:Internal Server Error: /batch/
Traceback (most recent call last):
  File "/home/rahul/anaconda3/envs/tracker/lib/python3.10/site-packages/django/core/handlers/exception.py", line 56, in inner
    response = get_response(request)
  File "/home/rahul/anaconda3/envs/tracker/lib/python3.10/site-packages/django/core/handlers/base.py", line 197, in _get_response
    response = wrapped_callback(request, *callback_args, **callback_kwargs)
  File "/home/rahul/conda_ws/django_ws/email_tracker/tracking/views.py", line 108, in batch_email_view
    email_batch.emails.add(email)
  File "/home/rahul/anaconda3/envs/tracker/lib/python3.10/site-packages/django/db/models/fields/related_descriptors.py", line 1087, in add
    self._add_items(
  File "/home/rahul/anaconda3/envs/tracker/lib/python3.10/site-packages/django/db/models/fields/related_descriptors.py", line 1323, in _add_items
    target_ids = self._get_target_ids(target_field_name, objs)
  File "/home/rahul/anaconda3/envs/tracker/lib/python3.10/site-packages/django/db/models/fields/related_descriptors.py", line 1239, in _get_target_ids
    raise ValueError(
ValueError: Cannot add "<Email: Email object (None)>": instance is on database "default", value is on database "None"
INFO:django.utils.autoreload:/home/rahul/conda_ws/django_ws/email_tracker/tracking/views.py changed, reloading.
WARNING:django.request:Not Found: /favicon.ico
INFO:django.utils.autoreload:/home/rahul/conda_ws/django_ws/email_tracker/tracking/views.py changed, reloading.
INFO:django.utils.autoreload:/home/rahul/conda_ws/django_ws/email_tracker/tracking/views.py changed, reloading.
INFO:django.utils.autoreload:/home/rahul/conda_ws/django_ws/email_tracker/tracking/tasks.py changed, reloading.
INFO:django.utils.autoreload:/home/rahul/conda_ws/django_ws/email_tracker/tracking/models.py changed, reloading.
INFO:django.utils.autoreload:/home/rahul/conda_ws/django_ws/email_tracker/tracking/models.py changed, reloading.
INFO:django.utils.autoreload:/home/rahul/conda_ws/django_ws/email_tracker/tracking/forms.py changed, reloading.
INFO:django.utils.autoreload:/home/rahul/conda_ws/django_ws/email_tracker/tracking/views.py changed, reloading.
INFO:django.utils.autoreload:/home/rahul/conda_ws/django_ws/email_tracker/tracking/tasks.py changed, reloading.
INFO:django.utils.autoreload:/home/rahul/conda_ws/django_ws/email_tracker/email_tracker/celery.py changed, reloading.
INFO:django.utils.autoreload:/home/rahul/conda_ws/django_ws/email_tracker/tracking/tasks.py changed, reloading.
ERROR:django.request:Internal Server Error: /batch/
Traceback (most recent call last):
  File "/home/rahul/anaconda3/envs/tracker/lib/python3.10/site-packages/django/db/backends/utils.py", line 89, in _execute
    return self.cursor.execute(sql, params)
  File "/home/rahul/anaconda3/envs/tracker/lib/python3.10/site-packages/django/db/backends/sqlite3/base.py", line 357, in execute
    return Database.Cursor.execute(self, query, params)
sqlite3.OperationalError: table tracking_emailbatch has no column named recipients

The above exception was the direct cause of the following exception:

Traceback (most recent call last):
  File "/home/rahul/anaconda3/envs/tracker/lib/python3.10/site-packages/django/core/handlers/exception.py", line 56, in inner
    response = get_response(request)
  File "/home/rahul/anaconda3/envs/tracker/lib/python3.10/site-packages/django/core/handlers/base.py", line 197, in _get_response
    response = wrapped_callback(request, *callback_args, **callback_kwargs)
  File "/home/rahul/conda_ws/django_ws/email_tracker/tracking/views.py", line 111, in batch_email_view
    email_batch.save()
  File "/home/rahul/anaconda3/envs/tracker/lib/python3.10/site-packages/django/db/models/base.py", line 812, in save
    self.save_base(
  File "/home/rahul/anaconda3/envs/tracker/lib/python3.10/site-packages/django/db/models/base.py", line 863, in save_base
    updated = self._save_table(
  File "/home/rahul/anaconda3/envs/tracker/lib/python3.10/site-packages/django/db/models/base.py", line 1006, in _save_table
    results = self._do_insert(
  File "/home/rahul/anaconda3/envs/tracker/lib/python3.10/site-packages/django/db/models/base.py", line 1047, in _do_insert
    return manager._insert(
  File "/home/rahul/anaconda3/envs/tracker/lib/python3.10/site-packages/django/db/models/manager.py", line 85, in manager_method
    return getattr(self.get_queryset(), name)(*args, **kwargs)
  File "/home/rahul/anaconda3/envs/tracker/lib/python3.10/site-packages/django/db/models/query.py", line 1791, in _insert
    return query.get_compiler(using=using).execute_sql(returning_fields)
  File "/home/rahul/anaconda3/envs/tracker/lib/python3.10/site-packages/django/db/models/sql/compiler.py", line 1660, in execute_sql
    cursor.execute(sql, params)
  File "/home/rahul/anaconda3/envs/tracker/lib/python3.10/site-packages/django/db/backends/utils.py", line 102, in execute
    return super().execute(sql, params)
  File "/home/rahul/anaconda3/envs/tracker/lib/python3.10/site-packages/django/db/backends/utils.py", line 67, in execute
    return self._execute_with_wrappers(
  File "/home/rahul/anaconda3/envs/tracker/lib/python3.10/site-packages/django/db/backends/utils.py", line 80, in _execute_with_wrappers
    return executor(sql, params, many, context)
  File "/home/rahul/anaconda3/envs/tracker/lib/python3.10/site-packages/django/db/backends/utils.py", line 84, in _execute
    with self.db.wrap_database_errors:
  File "/home/rahul/anaconda3/envs/tracker/lib/python3.10/site-packages/django/db/utils.py", line 91, in __exit__
    raise dj_exc_value.with_traceback(traceback) from exc_value
  File "/home/rahul/anaconda3/envs/tracker/lib/python3.10/site-packages/django/db/backends/utils.py", line 89, in _execute
    return self.cursor.execute(sql, params)
  File "/home/rahul/anaconda3/envs/tracker/lib/python3.10/site-packages/django/db/backends/sqlite3/base.py", line 357, in execute
    return Database.Cursor.execute(self, query, params)
django.db.utils.OperationalError: table tracking_emailbatch has no column named recipients
ERROR:django.request:Internal Server Error: /batch/
Traceback (most recent call last):
  File "/home/rahul/anaconda3/envs/tracker/lib/python3.10/site-packages/django/core/handlers/exception.py", line 56, in inner
    response = get_response(request)
  File "/home/rahul/anaconda3/envs/tracker/lib/python3.10/site-packages/django/core/handlers/base.py", line 197, in _get_response
    response = wrapped_callback(request, *callback_args, **callback_kwargs)
  File "/home/rahul/conda_ws/django_ws/email_tracker/tracking/views.py", line 114, in batch_email_view
    schedule_next_batch(email_batch)
  File "/home/rahul/conda_ws/django_ws/email_tracker/tracking/views.py", line 126, in schedule_next_batch
    if send_time <= now:
TypeError: can't compare offset-naive and offset-aware datetimes
INFO:django.utils.autoreload:/home/rahul/conda_ws/django_ws/email_tracker/tracking/scheduling.py changed, reloading.
ERROR:django.request:Internal Server Error: /batch/
Traceback (most recent call last):
  File "/home/rahul/anaconda3/envs/tracker/lib/python3.10/site-packages/django/core/handlers/exception.py", line 56, in inner
    response = get_response(request)
  File "/home/rahul/anaconda3/envs/tracker/lib/python3.10/site-packages/django/core/handlers/base.py", line 197, in _get_response
    response = wrapped_callback(request, *callback_args, **callback_kwargs)
  File "/home/rahul/conda_ws/django_ws/email_tracker/tracking/views.py", line 114, in batch_email_view
    schedule_next_batch(email_batch)
  File "/home/rahul/conda_ws/django_ws/email_tracker/tracking/views.py", line 126, in schedule_next_batch
    if send_time <= now:
TypeError: can't compare offset-naive and offset-aware datetimes
INFO:django.utils.autoreload:/home/rahul/conda_ws/django_ws/email_tracker/tracking/models.py changed, reloading.
INFO:django.utils.autoreload:/home/rahul/conda_ws/django_ws/email_tracker/tracking/models.py changed, reloading.
INFO:django.utils.autoreload:/home/rahul/conda_ws/django_ws/email_tracker/tracking/models.py changed, reloading.
INFO:django.utils.autoreload:/home/rahul/conda_ws/django_ws/email_tracker/tracking/scheduling.py changed, reloading.
ERROR:django.request:Internal Server Error: /batch/
Traceback (most recent call last):
  File "/home/rahul/anaconda3/envs/tracker/lib/python3.10/site-packages/django/core/handlers/exception.py", line 56, in inner
    response = get_response(request)
  File "/home/rahul/anaconda3/envs/tracker/lib/python3.10/site-packages/django/core/handlers/base.py", line 197, in _get_response
    response = wrapped_callback(request, *callback_args, **callback_kwargs)
  File "/home/rahul/conda_ws/django_ws/email_tracker/tracking/views.py", line 114, in batch_email_view
    schedule_next_batch(email_batch)
  File "/home/rahul/conda_ws/django_ws/email_tracker/tracking/views.py", line 126, in schedule_next_batch
    if send_time <= now:
TypeError: can't compare offset-naive and offset-aware datetimes
ERROR:django.request:Internal Server Error: /batch/
Traceback (most recent call last):
  File "/home/rahul/anaconda3/envs/tracker/lib/python3.10/site-packages/django/core/handlers/exception.py", line 56, in inner
    response = get_response(request)
  File "/home/rahul/anaconda3/envs/tracker/lib/python3.10/site-packages/django/core/handlers/base.py", line 197, in _get_response
    response = wrapped_callback(request, *callback_args, **callback_kwargs)
  File "/home/rahul/conda_ws/django_ws/email_tracker/tracking/views.py", line 114, in batch_email_view
    schedule_next_batch(email_batch)
  File "/home/rahul/conda_ws/django_ws/email_tracker/tracking/views.py", line 126, in schedule_next_batch
    if send_time <= now:
TypeError: can't compare offset-naive and offset-aware datetimes
INFO:django.utils.autoreload:/home/rahul/conda_ws/django_ws/email_tracker/tracking/models.py changed, reloading.
INFO:django.utils.autoreload:/home/rahul/conda_ws/django_ws/email_tracker/tracking/scheduling.py changed, reloading.
INFO:django.utils.autoreload:/home/rahul/conda_ws/django_ws/email_tracker/tracking/views.py changed, reloading.
INFO:django.utils.autoreload:/home/rahul/conda_ws/django_ws/email_tracker/tracking/views.py changed, reloading.
WARNING:django.request:Not Found: /favicon.ico
INFO:django.utils.autoreload:/home/rahul/conda_ws/django_ws/email_tracker/email_tracker/settings.py changed, reloading.
ERROR:django.security.DisallowedHost:Invalid HTTP_HOST header: 'b28d-2405-201-5009-6022-8fef-7e89-a12e-b610.ngrok-free.app'. You may need to add 'b28d-2405-201-5009-6022-8fef-7e89-a12e-b610.ngrok-free.app' to ALLOWED_HOSTS.
Traceback (most recent call last):
  File "/home/rahul/anaconda3/envs/tracker/lib/python3.10/site-packages/django/core/handlers/exception.py", line 56, in inner
    response = get_response(request)
  File "/home/rahul/anaconda3/envs/tracker/lib/python3.10/site-packages/django/utils/deprecation.py", line 135, in __call__
    response = self.process_request(request)
  File "/home/rahul/anaconda3/envs/tracker/lib/python3.10/site-packages/django/middleware/common.py", line 48, in process_request
    host = request.get_host()
  File "/home/rahul/anaconda3/envs/tracker/lib/python3.10/site-packages/django/http/request.py", line 152, in get_host
    raise DisallowedHost(msg)
django.core.exceptions.DisallowedHost: Invalid HTTP_HOST header: 'b28d-2405-201-5009-6022-8fef-7e89-a12e-b610.ngrok-free.app'. You may need to add 'b28d-2405-201-5009-6022-8fef-7e89-a12e-b610.ngrok-free.app' to ALLOWED_HOSTS.
WARNING:django.request:Bad Request: /batch
ERROR:django.security.DisallowedHost:Invalid HTTP_HOST header: 'b28d-2405-201-5009-6022-8fef-7e89-a12e-b610.ngrok-free.app'. You may need to add 'b28d-2405-201-5009-6022-8fef-7e89-a12e-b610.ngrok-free.app' to ALLOWED_HOSTS.
Traceback (most recent call last):
  File "/home/rahul/anaconda3/envs/tracker/lib/python3.10/site-packages/django/core/handlers/exception.py", line 56, in inner
    response = get_response(request)
  File "/home/rahul/anaconda3/envs/tracker/lib/python3.10/site-packages/django/utils/deprecation.py", line 135, in __call__
    response = self.process_request(request)
  File "/home/rahul/anaconda3/envs/tracker/lib/python3.10/site-packages/django/middleware/common.py", line 48, in process_request
    host = request.get_host()
  File "/home/rahul/anaconda3/envs/tracker/lib/python3.10/site-packages/django/http/request.py", line 152, in get_host
    raise DisallowedHost(msg)
django.core.exceptions.DisallowedHost: Invalid HTTP_HOST header: 'b28d-2405-201-5009-6022-8fef-7e89-a12e-b610.ngrok-free.app'. You may need to add 'b28d-2405-201-5009-6022-8fef-7e89-a12e-b610.ngrok-free.app' to ALLOWED_HOSTS.
WARNING:django.request:Bad Request: /favicon.ico
INFO:django.utils.autoreload:/home/rahul/conda_ws/django_ws/email_tracker/email_tracker/settings.py changed, reloading.
WARNING:django.request:Not Found: /favicon.ico
WARNING:django.security.csrf:Forbidden (Origin checking failed - https://b28d-2405-201-5009-6022-8fef-7e89-a12e-b610.ngrok-free.app does not match any trusted origins.): /batch/
INFO:django.utils.autoreload:/home/rahul/conda_ws/django_ws/email_tracker/email_tracker/settings.py changed, reloading.
WARNING:django.request:Not Found: /favicon.ico
WARNING:django.request:Not Found: /apple-touch-icon.png
WARNING:django.request:Not Found: /favicon.ico
INFO:django.utils.autoreload:/home/rahul/conda_ws/django_ws/email_tracker/email_tracker/settings.py changed, reloading.
INFO:django.utils.autoreload:/home/rahul/conda_ws/django_ws/email_tracker/email_tracker/settings.py changed, reloading.
INFO:django.utils.autoreload:/home/rahul/conda_ws/django_ws/email_tracker/email_tracker/settings.py changed, reloading.
INFO:django.utils.autoreload:/home/rahul/conda_ws/django_ws/email_tracker/email_tracker/settings.py changed, reloading.
INFO:django.utils.autoreload:/home/rahul/conda_ws/django_ws/email_tracker/email_tracker/settings.py changed, reloading.
INFO:django.utils.autoreload:/home/rahul/conda_ws/django_ws/email_tracker/email_tracker/settings.py changed, reloading.
INFO:django.utils.autoreload:/home/rahul/conda_ws/django_ws/email_tracker/email_tracker/settings.py changed, reloading.
INFO:django.utils.autoreload:/home/rahul/conda_ws/django_ws/email_tracker/email_tracker/settings.py changed, reloading.
WARNING:django.request:Not Found: /favicon.ico
WARNING:django.request:Not Found: /favicon.ico
INFO:root:This is debug message
